<mujoco model="car">
  <compiler inertiafromgeom="true"/>
  <option timestep="0.002" gravity="0 0 -9.81"/>

  <asset>
    <texture name="grid" type="2d" builtin="checker"
             rgb1="0.2 0.3 0.4" rgb2="0.8 0.8 0.8"
             width="512" height="512"/>
    <material name="grid_mat" texture="grid" texrepeat="5 5"
              specular="0.3" shininess="0.3"/>
    <texture name="wheel_pattern" type="2d" builtin="checker"
             rgb1="1 1 1" rgb2="0 0 0"
             width="64" height="64"/>
    <material name="wheel_mat" texture="wheel_pattern" texrepeat="8 1"
              specular="0.5" shininess="0.5"/>
  </asset>

  <worldbody>
    <geom name="floor" type="plane" size="150 150 0.3"
          rgba="0.8 0.8 0.8 1" material="grid_mat"
          friction="0.8 0.005 0.0001"/>

    <body name="chassis" pos="0 0 0.15">
      <joint name="x"   type="slide" axis="1 0 0" damping="0.1"/>
      <joint name="y"   type="slide" axis="0 1 0" damping="0.1"/>
      <joint name="rot" type="hinge" axis="0 0 1" damping="0.1"/>

      <geom name="chassis" type="box" size="0.45 0.3 0.09"
            rgba="1 0 0 1" mass="100.0"/>
      <geom name="front" type="box" size="0.15 0.09 0.03"
            pos="0.3 0 0.09" rgba="0 1 0 1"/>
      <geom name="rear"  type="box" size="0.15 0.09 0.03"
            pos="-0.3 0 0.09" rgba="0 0 1 1"/>

      <!-- ✅ 운전석 센서 부착 위치 (site) -->
      <site name="driver_seat" pos="0 0 0.24" size="0.015"
            rgba="1 0 1 0.5"/>

      <!-- 앞왼쪽 바퀴 -->
      <body name="fl_susp" pos="0.3 0.36 0.0">
        <inertial pos="0 0 0" mass="1" diaginertia="0.001 0.001 0.001"/>
        <joint name="fl_suspension" type="slide" axis="0 0 1" damping="2"/>

        <body name="front_left_wheel" pos="0 0 -0.09">
          <joint name="fl_steer" type="hinge" axis="0 0 1" range="-0.6 0.6" damping="0.05"/>
          <joint name="fl_wheel" type="hinge" axis="0 1 0" damping="0.01"/>
          <geom name="fl_geom" type="cylinder" size="0.09 0.045"
                euler="90 0 0" material="wheel_mat"
                mass="0.1" friction="0.8 0.005 0.0001"/>
        </body>
      </body>

      <!-- 앞오른쪽 바퀴 -->
      <body name="fr_susp" pos="0.3 -0.36 0.0">
        <inertial pos="0 0 0" mass="1" diaginertia="0.001 0.001 0.001"/>
        <joint name="fr_suspension" type="slide" axis="0 0 1" damping="2"/>

        <body name="front_right_wheel" pos="0 0 -0.09">
          <joint name="fr_steer" type="hinge" axis="0 0 1" range="-0.6 0.6" damping="0.05"/>
          <joint name="fr_wheel" type="hinge" axis="0 1 0" damping="0.01"/>
          <geom name="fr_geom" type="cylinder" size="0.09 0.045"
                euler="90 0 0" material="wheel_mat"
                mass="0.1" friction="0.8 0.005 0.0001"/>
        </body>
      </body>

      <!-- 뒤왼쪽 바퀴 -->
      <body name="rl_susp" pos="-0.3 0.36 0.0">
        <inertial pos="0 0 0" mass="1" diaginertia="0.001 0.001 0.001"/>
        <joint name="rl_suspension" type="slide" axis="0 0 1" damping="2"/>

        <body name="rear_left_wheel" pos="0 0 -0.09">
          <joint name="rl_wheel" type="hinge" axis="0 1 0" damping="0.01"/>
          <geom name="rl_geom" type="cylinder" size="0.09 0.045"
                euler="90 0 0" material="wheel_mat"
                mass="0.1" friction="0.8 0.005 0.0001"/>
        </body>
      </body>

      <!-- 뒤오른쪽 바퀴 -->
      <body name="rr_susp" pos="-0.3 -0.36 0.0">
        <inertial pos="0 0 0" mass="1" diaginertia="0.001 0.001 0.001"/>
        <joint name="rr_suspension" type="slide" axis="0 0 1" damping="2"/>

        <body name="rear_right_wheel" pos="0 0 -0.09">
          <joint name="rr_wheel" type="hinge" axis="0 1 0" damping="0.01"/>
          <geom name="rr_geom" type="cylinder" size="0.09 0.045"
                euler="90 0 0" material="wheel_mat"
                mass="0.1" friction="0.8 0.005 0.0001"/>
        </body>
      </body>

    </body>
  </worldbody>

  <sensor>
    <!-- ✅ 운전석 기준 vertical 가속도 -->
    <accelerometer name="accel_z" site="driver_seat"/>
    <!-- ✅ pitch 확인용 자이로 (z축은 yaw, pitch는 x축 기준) -->
    <gyro name="gyro_pitch" site="driver_seat"/>
  </sensor>

  <actuator>
    <motor name="fl_motor" joint="fl_wheel" ctrlrange="-10 10" gear="0.1"/>
    <motor name="fr_motor" joint="fr_wheel" ctrlrange="-10 10" gear="0.1"/>
    <motor name="rl_motor" joint="rl_wheel" ctrlrange="-10 10" gear="0.1"/>
    <motor name="rr_motor" joint="rr_wheel" ctrlrange="-10 10" gear="0.1"/>

    <motor name="fl_steer" joint="fl_steer" ctrlrange="-0.6 0.6" gear="1"/>
    <motor name="fr_steer" joint="fr_steer" ctrlrange="-0.6 0.6" gear="1"/>

    <general name="fl_spring" joint="fl_suspension" gainprm="0 0 0" biasprm="0 1000 10"/>
    <general name="fr_spring" joint="fr_suspension" gainprm="0 0 0" biasprm="0 1000 10"/>
    <general name="rl_spring" joint="rl_suspension" gainprm="0 0 0" biasprm="0 1000 10"/>
    <general name="rr_spring" joint="rr_suspension" gainprm="0 0 0" biasprm="0 1000 10"/>
  </actuator>
</mujoco>
